<?xml version='1.0' encoding='utf-8'?>
<sdf version="1.11">
  <model name="k9_robot">
    <link name="base_footprint">
      <inertial>
        <pose>-0.018087371512481638 0 0.2223360352422907 0 0 0</pose>
        <mass>27.239999999999998</mass>
        <inertia>
          <ixx>1.0186533306718071</ixx>
          <ixy>0</ixy>
          <ixz>-0.018856511563876629</ixz>
          <iyy>2.4546292827276068</iyy>
          <iyz>0</iyz>
          <izz>2.0486979520558011</izz>
        </inertia>
      </inertial>
      <collision name="base_footprint_fixed_joint_lump__base_link_collision">
        <pose>-0.11899999999999999 0 0.38439000000000001 0 0 0</pose>
        <geometry>
          <box>
            <size>0.89000000000000001 0.48999999999999999 0.34999999999999998</size>
          </box>
        </geometry>
      </collision>
      <collision name="base_footprint_fixed_joint_lump__base_link_collision_1">
        <pose>0.33600000000000002 0 0.68189 0 0 0</pose>
        <geometry>
          <box>
            <size>0.42999999999999999 0.17999999999999999 0.29499999999999998</size>
          </box>
        </geometry>
      </collision>
      <visual name="base_footprint_fixed_joint_lump__base_link_visual">
        <pose>-0.5 1.905 0.069389999999999993 0 0 3.1415926535897931</pose>
        <geometry>
          <mesh>
            <scale>0.01 0.01 0.01</scale>
            <uri>file:///home/hopkira/Documents/GitHub/k9-gazebo/src/k9_description/urdf/k9.stl</uri>
          </mesh>
        </geometry>
        <material>
          <diffuse>0.3125 0.3125 0.3125 0.300000012</diffuse>
          <ambient>0.3125 0.3125 0.3125 0.300000012</ambient>
        </material>
      </visual>
    </link>
    <joint name="caster_swivel_joint" type="revolute">
      <pose relative_to="base_footprint">-0.29799999999999999 0 0.017999999999999999 0 0 0</pose>
      <parent>base_footprint</parent>
      <child>caster_swivel_link</child>
      <axis>
        <xyz>0 0 1</xyz>
        <limit>
          <lower>-inf</lower>
          <upper>inf</upper>
        </limit>
        <dynamics>
          <damping>0.80000000000000004</damping>
          <friction>0</friction>
          <spring_reference>0</spring_reference>
          <spring_stiffness>0</spring_stiffness>
        </dynamics>
      </axis>
    </joint>
    <link name="caster_swivel_link">
      <pose relative_to="caster_swivel_joint">0 0 0 0 0 0</pose>
      <inertial>
        <pose>0 0 0 0 0 0</pose>
        <mass>0.14999999999999999</mass>
        <inertia>
          <ixx>1.365e-05</ixx>
          <ixy>0</ixy>
          <ixz>0</ixz>
          <iyy>1.365e-05</iyy>
          <iyz>0</iyz>
          <izz>4.7999999999999998e-06</izz>
        </inertia>
      </inertial>
      <collision name="caster_swivel_link_collision">
        <pose>0 0 0 0 0 0</pose>
        <geometry>
          <cylinder>
            <length>0.029999999999999999</length>
            <radius>0.0080000000000000002</radius>
          </cylinder>
        </geometry>
      </collision>
      <visual name="caster_swivel_link_visual">
        <pose>0 0 0 0 0 0</pose>
        <geometry>
          <cylinder>
            <length>0.029999999999999999</length>
            <radius>0.0080000000000000002</radius>
          </cylinder>
        </geometry>
        <material>
          <diffuse>0.875 0.875 0.875 1</diffuse>
          <ambient>0.875 0.875 0.875 1</ambient>
        </material>
      </visual>
    </link>
    <joint name="caster_wheel_joint" type="revolute">
      <pose relative_to="caster_swivel_link">-0.017999999999999999 0 0 0 0 0</pose>
      <parent>caster_swivel_link</parent>
      <child>caster_wheel_link</child>
      <axis>
        <xyz>0 1 0</xyz>
        <limit>
          <lower>-inf</lower>
          <upper>inf</upper>
        </limit>
        <dynamics>
          <damping>0.10000000000000001</damping>
          <friction>0</friction>
          <spring_reference>0</spring_reference>
          <spring_stiffness>0</spring_stiffness>
        </dynamics>
      </axis>
    </joint>
    <link name="caster_wheel_link">
      <pose relative_to="caster_wheel_joint">0 0 0 0 0 0</pose>
      <inertial>
        <pose>0 0 0 0 0 0</pose>
        <mass>0.10000000000000001</mass>
        <inertia>
          <ixx>1.1199999999999999e-05</ixx>
          <ixy>0</ixy>
          <ixz>0</ixz>
          <iyy>1.1199999999999999e-05</iyy>
          <iyz>0</iyz>
          <izz>2.0000000000000002e-05</izz>
        </inertia>
      </inertial>
      <collision name="caster_wheel_link_collision">
        <pose>0 0 0 1.5707963267948959 0 0</pose>
        <geometry>
          <cylinder>
            <length>0.012</length>
            <radius>0.02</radius>
          </cylinder>
        </geometry>
        <surface>
          <contact>
            <ode />
          </contact>
          <friction>
            <ode>
              <mu>0.3</mu>
              <mu2>0.15</mu2>
            </ode>
          </friction>
        </surface>
      </collision>
      <visual name="caster_wheel_link_visual">
        <pose>0 0 0 1.5707963267948959 0 0</pose>
        <geometry>
          <cylinder>
            <length>0.012</length>
            <radius>0.02</radius>
          </cylinder>
        </geometry>
        <material>
          <diffuse>0.875 0.875 0.875 1</diffuse>
          <ambient>0.875 0.875 0.875 1</ambient>
        </material>
      </visual>
    </link>
    <joint name="drivewhl_l_joint" type="revolute">
      <pose relative_to="base_footprint">0 0.1011 0.069389999999999993 0 0 0</pose>
      <parent>base_footprint</parent>
      <child>drivewhl_l_link</child>
      <axis>
        <xyz>0 1 0</xyz>
        <limit>
          <lower>-inf</lower>
          <upper>inf</upper>
        </limit>
        <dynamics>
          <damping>0.050000000000000003</damping>
          <friction>0</friction>
          <spring_reference>0</spring_reference>
          <spring_stiffness>0</spring_stiffness>
        </dynamics>
      </axis>
    </joint>
    <link name="drivewhl_l_link">
      <pose relative_to="drivewhl_l_joint">0 0 0 0 0 0</pose>
      <inertial>
        <pose>0 0 0 0 0 0</pose>
        <mass>0.29999999999999999</mass>
        <inertia>
          <ixx>0.00037674790749999987</ixx>
          <ixy>0</ixy>
          <ixz>0</ixz>
          <iyy>0.00037674790749999987</iyy>
          <iyz>0</iyz>
          <izz>0.00072224581499999994</izz>
        </inertia>
      </inertial>
      <collision name="drivewhl_l_link_collision">
        <pose>0 0 0 1.5707963267948959 0 0</pose>
        <geometry>
          <cylinder>
            <length>0.025000000000000001</length>
            <radius>0.069389999999999993</radius>
          </cylinder>
        </geometry>
        <surface>
          <contact>
            <ode />
          </contact>
          <friction>
            <ode>
              <mu>1.1</mu>
              <mu2>0.9</mu2>
            </ode>
          </friction>
        </surface>
      </collision>
      <visual name="drivewhl_l_link_visual">
        <pose>0 0 0 1.5707963267948959 0 0</pose>
        <geometry>
          <cylinder>
            <length>0.025000000000000001</length>
            <radius>0.069389999999999993</radius>
          </cylinder>
        </geometry>
        <material>
          <diffuse>0.875 0.875 0.875 1</diffuse>
          <ambient>0.875 0.875 0.875 1</ambient>
        </material>
      </visual>
    </link>
    <joint name="drivewhl_r_joint" type="revolute">
      <pose relative_to="base_footprint">0 -0.1011 0.069389999999999993 0 0 0</pose>
      <parent>base_footprint</parent>
      <child>drivewhl_r_link</child>
      <axis>
        <xyz>0 1 0</xyz>
        <limit>
          <lower>-inf</lower>
          <upper>inf</upper>
        </limit>
        <dynamics>
          <damping>0.050000000000000003</damping>
          <friction>0</friction>
          <spring_reference>0</spring_reference>
          <spring_stiffness>0</spring_stiffness>
        </dynamics>
      </axis>
    </joint>
    <link name="drivewhl_r_link">
      <pose relative_to="drivewhl_r_joint">0 0 0 0 0 0</pose>
      <inertial>
        <pose>0 0 0 0 0 0</pose>
        <mass>0.29999999999999999</mass>
        <inertia>
          <ixx>0.00037674790749999987</ixx>
          <ixy>0</ixy>
          <ixz>0</ixz>
          <iyy>0.00037674790749999987</iyy>
          <iyz>0</iyz>
          <izz>0.00072224581499999994</izz>
        </inertia>
      </inertial>
      <collision name="drivewhl_r_link_collision">
        <pose>0 0 0 1.5707963267948959 0 0</pose>
        <geometry>
          <cylinder>
            <length>0.025000000000000001</length>
            <radius>0.069389999999999993</radius>
          </cylinder>
        </geometry>
        <surface>
          <contact>
            <ode />
          </contact>
          <friction>
            <ode>
              <mu>1.1</mu>
              <mu2>0.9</mu2>
            </ode>
          </friction>
        </surface>
      </collision>
      <visual name="drivewhl_r_link_visual">
        <pose>0 0 0 1.5707963267948959 0 0</pose>
        <geometry>
          <cylinder>
            <length>0.025000000000000001</length>
            <radius>0.069389999999999993</radius>
          </cylinder>
        </geometry>
        <material>
          <diffuse>0.875 0.875 0.875 1</diffuse>
          <ambient>0.875 0.875 0.875 1</ambient>
        </material>
      </visual>
    </link>
    <plugin name="gz::sim::systems::DiffDrive" filename="gz-sim-diff-drive-system">
      <left_joint>drivewhl_l_joint</left_joint>
      <right_joint>drivewhl_r_joint</right_joint>
      <wheel_separation>0.2022</wheel_separation>
      <wheel_radius>0.06939</wheel_radius>
      <odom_publish_frequency>50</odom_publish_frequency>
      <topic>/cmd_vel</topic>
      <odom_topic>/odom</odom_topic>
      <tf_topic>/tf</tf_topic>
      <frame_id>odom</frame_id>
      <child_frame_id>base_footprint</child_frame_id>
    </plugin>
    <frame name="3dcam_joint" attached_to="base_link">
      <pose>0.20599999999999999 0 0.255 0 0 0</pose>
    </frame>
    <frame name="3dcam_link" attached_to="3dcam_joint">
      <pose>0 0 0 0 0 0</pose>
    </frame>
    <frame name="eyecam_joint" attached_to="base_link">
      <pose>0.36599999999999999 0 0.67000000000000004 0 0 0</pose>
    </frame>
    <frame name="eyecam_link" attached_to="eyecam_joint">
      <pose>0 0 0 0 0 0</pose>
    </frame>
    <frame name="l_ear_joint" attached_to="base_link">
      <pose>0.34999999999999998 0.044999999999999998 0.72499999999999998 0 0.65000000000000002 0</pose>
    </frame>
    <frame name="l_ear_link" attached_to="l_ear_joint">
      <pose>0 0 0 0 0 0</pose>
    </frame>
    <frame name="lidar_joint" attached_to="base_link">
      <pose>-0.112 0 0.56499999999999995 0 0 0</pose>
    </frame>
    <frame name="lidar_link" attached_to="lidar_joint">
      <pose>0 0 0 0 0 0</pose>
    </frame>
    <frame name="r_ear_joint" attached_to="base_link">
      <pose>0.34999999999999998 -0.044999999999999998 0.72499999999999998 0 0.65000000000000002 0</pose>
    </frame>
    <frame name="r_ear_link" attached_to="r_ear_joint">
      <pose>0 0 0 0 0 0</pose>
    </frame>
    <frame name="base_joint" attached_to="base_footprint">
      <pose>0 0 0.069389999999999993 0 0 0</pose>
    </frame>
    <frame name="base_link" attached_to="base_joint">
      <pose>0 0 0 0 0 0</pose>
    </frame>
  </model>
</sdf>