<?xml version="1.0" ?>
<!-- =================================================================================== -->
<!-- |    This document was autogenerated by xacro from k9.urdf.xacro                  | -->
<!-- |    EDITING THIS FILE BY HAND IS NOT RECOMMENDED                                 | -->
<!-- =================================================================================== -->
<robot name="k9_robot">
  <!-- ===================================================== -->
  <!-- Materials                                             -->
  <!-- ===================================================== -->
  <material name="K9_grey">
    <color rgba="0.25 0.25 0.25 1.0"/>
  </material>
  <material name="wheel_grey">
    <color rgba="0.7 0.7 0.7 1.0"/>
  </material>
  <!-- ===================================================== -->
  <!-- Frames                                                -->
  <!-- ===================================================== -->
  <link name="base_footprint"/>
  <!-- ===================================================== -->
  <!-- Base / chassis                                        -->
  <!-- ===================================================== -->
  <link name="base_link">
    <!-- Visual -->
    <visual>
      <origin rpy="0 0 3.141592653589793" xyz="-0.5 1.905 -0.0694"/>
      <geometry>
        <mesh filename="file:///home/hopkira/Documents/GitHub/k9-gazebo/src/k9_description/urdf/k9.stl" scale="0.01 0.01 0.01"/>
      </geometry>
      <material name="K9_grey"/>
    </visual>
    <!-- Collision -->
    <collision>
      <origin xyz="0.0 0.0 0.44"/>
      <geometry>
        <box size="1.05 0.49 0.74"/>
      </geometry>
    </collision>
    <!-- Inertia: main shell + structure -->
    <!-- CHANGED: lower + slightly rear-shift COM, and increase pitch inertia (iyy) -->
    <inertial>
      <!-- was: -0.02 0 0.20 -->
      <origin xyz="-0.06 0 0.16"/>
      <mass value="19.0"/>
      <inertia ixx="0.80" ixy="0" ixz="0" iyy="2.40" iyz="0" izz="1.70"/>
    </inertial>
  </link>
  <joint name="base_joint" type="fixed">
    <parent link="base_footprint"/>
    <child link="base_link"/>
    <origin xyz="0 0 0.0694"/>
  </joint>
  <!-- ===================================================== -->
  <!-- Battery (low + central)                               -->
  <!-- ===================================================== -->
  <link name="battery_link">
    <collision>
      <geometry>
        <box size="0.25 0.20 0.25"/>
      </geometry>
    </collision>
    <inertial>
      <origin xyz="0 0 0"/>
      <mass value="5.0"/>
      <inertia ixx="1e-4" ixy="0" ixz="0" iyy="1e-4" iyz="0" izz="1e-4"/>
    </inertial>
  </link>
  <joint name="battery_joint" type="fixed">
    <parent link="base_link"/>
    <child link="battery_link"/>
    <origin xyz="0 0 0.18"/>
  </joint>
  <!-- ===================================================== -->
  <!-- Motors                                                -->
  <!-- ===================================================== -->
  <link name="motors_link">
    <collision>
      <geometry>
        <box size="0.20 0.20 0.10"/>
      </geometry>
    </collision>
    <inertial>
      <origin xyz="0 0 0"/>
      <mass value="3.0"/>
      <inertia ixx="1e-4" ixy="0" ixz="0" iyy="1e-4" iyz="0" izz="1e-4"/>
    </inertial>
  </link>
  <joint name="motors_joint" type="fixed">
    <parent link="base_link"/>
    <child link="motors_link"/>
    <origin xyz="0 0 0.10"/>
  </joint>
  <link name="drivewhl_l_link">
    <visual>
      <origin rpy="1.5707963267948966 0 0"/>
      <geometry>
        <cylinder length="0.025" radius="0.0694"/>
      </geometry>
      <material name="wheel_grey"/>
    </visual>
    <collision>
      <origin rpy="1.5707963267948966 0 0"/>
      <geometry>
        <cylinder length="0.025" radius="0.0694"/>
      </geometry>
      <!-- NEW: slightly reduced friction to reduce "trip" under hard braking -->
      <surface>
        <friction>
          <ode>
            <mu>0.9</mu>
            <mu2>0.7</mu2>
          </ode>
        </friction>
      </surface>
    </collision>
    <inertial>
      <mass value="1.0"/>
      <inertia ixx="0.002" ixy="0" ixz="0" iyy="0.002" iyz="0" izz="0.004"/>
    </inertial>
  </link>
  <joint name="drivewhl_l_joint" type="continuous">
    <parent link="base_link"/>
    <child link="drivewhl_l_link"/>
    <origin xyz="0 0.1011 0"/>
    <axis xyz="0 1 0"/>
    <dynamics damping="0.05"/>
  </joint>
  <link name="drivewhl_r_link">
    <visual>
      <origin rpy="1.5707963267948966 0 0"/>
      <geometry>
        <cylinder length="0.025" radius="0.0694"/>
      </geometry>
      <material name="wheel_grey"/>
    </visual>
    <collision>
      <origin rpy="1.5707963267948966 0 0"/>
      <geometry>
        <cylinder length="0.025" radius="0.0694"/>
      </geometry>
      <!-- NEW: slightly reduced friction to reduce "trip" under hard braking -->
      <surface>
        <friction>
          <ode>
            <mu>0.9</mu>
            <mu2>0.7</mu2>
          </ode>
        </friction>
      </surface>
    </collision>
    <inertial>
      <mass value="1.0"/>
      <inertia ixx="0.002" ixy="0" ixz="0" iyy="0.002" iyz="0" izz="0.004"/>
    </inertial>
  </link>
  <joint name="drivewhl_r_joint" type="continuous">
    <parent link="base_link"/>
    <child link="drivewhl_r_link"/>
    <origin xyz="0 -0.1011 0"/>
    <axis xyz="0 1 0"/>
    <dynamics damping="0.05"/>
  </joint>
  <!-- ===================================================== -->
  <!-- Ball caster (4 cm sphere)                              -->
  <!-- ===================================================== -->
  <link name="ball_caster_link">
    <visual>
      <geometry>
        <sphere radius="0.04"/>
      </geometry>
      <material name="wheel_grey"/>
    </visual>
    <collision>
      <geometry>
        <sphere radius="0.04"/>
      </geometry>
      <!-- NEW: low friction so it supports but doesn't brake/steer the robot -->
      <surface>
        <friction>
          <ode>
            <mu>0.2</mu>
            <mu2>0.2</mu2>
          </ode>
        </friction>
      </surface>
    </collision>
    <inertial>
      <origin xyz="0 0 0"/>
      <mass value="0.5"/>
      <inertia ixx="1e-4" ixy="0" ixz="0" iyy="1e-4" iyz="0" izz="1e-4"/>
    </inertial>
  </link>
  <joint name="ball_caster_joint" type="fixed">
    <parent link="base_link"/>
    <child link="ball_caster_link"/>
    <origin xyz="-0.3 0 -0.029400000000000003"/>
  </joint>
  <!-- ===================================================== -->
  <!-- Sensors                                               -->
  <!-- ===================================================== -->
  <!-- started at 0.565 raised by 20 cm to clear body       -->
  <link name="base_laser">
    <inertial>
      <origin xyz="0 0 0"/>
      <mass value="0.05"/>
      <inertia ixx="1e-4" ixy="0" ixz="0" iyy="1e-4" iyz="0" izz="1e-4"/>
    </inertial>
  </link>
  <joint name="base_laser_joint" type="fixed">
    <parent link="base_link"/>
    <child link="base_laser"/>
    <origin rpy="0 0 0" xyz="-0.112 0 0.53"/>
  </joint>
  <gazebo reference="base_laser">
    <sensor name="ld06_lidar" type="gpu_lidar">
      <update_rate>10</update_rate>
      <always_on>true</always_on>
      <topic>/world/empty/model/k9_robot/ld06/scan</topic>
      <pose>0 0 0 0 0 0</pose>
      <visualize>true</visualize>
      <lidar>
        <scan>
          <horizontal>
            <samples>360</samples>
            <min_angle>-3.14159</min_angle>
            <max_angle>3.14159</max_angle>
          </horizontal>
        </scan>
        <range>
          <min>0.02</min>
          <max>12.0</max>
        </range>
      </lidar>
      <always_on>true</always_on>
      <visualize>true</visualize>
    </sensor>
  </gazebo>
  <link name="eyecam_link">
    <inertial>
      <origin xyz="0 0 0"/>
      <mass value="0.05"/>
      <inertia ixx="1e-4" ixy="0" ixz="0" iyy="1e-4" iyz="0" izz="1e-4"/>
    </inertial>
  </link>
  <joint name="eyecam_joint" type="fixed">
    <parent link="base_link"/>
    <child link="eyecam_link"/>
    <origin xyz="0.366 0 0.67"/>
  </joint>
  <link name="3dcam_link">
    <inertial>
      <origin xyz="0 0 0"/>
      <mass value="0.1"/>
      <inertia ixx="1e-4" ixy="0" ixz="0" iyy="1e-4" iyz="0" izz="1e-4"/>
    </inertial>
  </link>
  <joint name="3dcam_joint" type="fixed">
    <parent link="base_link"/>
    <child link="3dcam_link"/>
    <origin xyz="0.206 0 0.255"/>
  </joint>
  <!-- ===================================================== -->
  <!-- Gazebo Diff Drive (gz-sim, Jazzy)                     -->
  <!-- ===================================================== -->
  <gazebo>
    <plugin filename="gz-sim-diff-drive-system" name="gz::sim::systems::DiffDrive">
      <left_joint>drivewhl_l_joint</left_joint>
      <right_joint>drivewhl_r_joint</right_joint>
      <wheel_separation>0.2022</wheel_separation>
      <wheel_radius>0.0694</wheel_radius>
      <max_linear_velocity>1.4</max_linear_velocity>
      <max_angular_velocity>0.63</max_angular_velocity>
      <!-- CHANGED: lower accel also caps braking decel (less "nose dive") -->
      <max_linear_acceleration>0.4</max_linear_acceleration>
      <max_angular_acceleration>0.4</max_angular_acceleration>
      <topic>/cmd_vel</topic>
      <odom_topic>/odom</odom_topic>
      <frame_id>odom</frame_id>
      <child_frame_id>base_footprint</child_frame_id>
    </plugin>
  </gazebo>
</robot>
