<?xml version="1.0" ?>
<!-- =================================================================================== -->
<!-- |    This document was autogenerated by xacro from k9.urdf.xacro                  | -->
<!-- |    EDITING THIS FILE BY HAND IS NOT RECOMMENDED                                 | -->
<!-- =================================================================================== -->
<robot name="k9_robot">
  <!-- ===================================================== -->
  <!-- To generate SDF for Gazebo Sim                        -->
  <!-- ros2 run xacro xacro k9.urdf.xacro > k9.urdf          -->
  <!-- gz sdf -p k9.urdf > k9_raw.sdf                        -->
  <!-- python3 patch_friction.py k9_raw.sdf k9_robot.sdf     -->
  <!-- ===================================================== -->
  <!-- ===================================================== -->
  <!-- Materials                                             -->
  <!-- ===================================================== -->
  <material name="K9_grey">
    <color rgba="0.25 0.25 0.25 1.0"/>
  </material>
  <material name="wheel_grey">
    <color rgba="0.7 0.7 0.7 1.0"/>
  </material>
  <material name="k9_ear_emissive">
    <color rgba="0 0 0 1"/>
  </material>
  <material name="k9_beam_material">
    <color rgba="0 1 0 1"/>
  </material>
  <!-- ===================================================== -->
  <!-- Frames                                                -->
  <!-- ===================================================== -->
  <link name="base_footprint"/>
  <!-- ===================================================== -->
  <!-- Base / chassis                                        -->
  <!-- ===================================================== -->
  <link name="base_link">
    <!-- Visual -->
    <visual>
      <origin rpy="0 0 3.141592653589793" xyz="-0.5 1.905 -0.0694"/>
      <geometry>
        <mesh filename="file:///home/hopkira/Documents/GitHub/k9-gazebo/src/k9_description/urdf/k9.stl" scale="0.01 0.01 0.01"/>
      </geometry>
      <material name="K9_grey"/>
    </visual>
    <!-- Collision -->
    <collision>
      <origin xyz="0.0 0.0 0.44"/>
      <geometry>
        <box size="1.05 0.49 0.74"/>
      </geometry>
    </collision>
    <!-- Inertia: main shell + structure -->
    <!-- CHANGED: lower + slightly rear-shift COM, and increase pitch inertia (iyy) -->
    <inertial>
      <!-- was: -0.02 0 0.20 -->
      <origin xyz="-0.06 0 0.16"/>
      <mass value="19.0"/>
      <inertia ixx="0.80" ixy="0" ixz="0" iyy="2.40" iyz="0" izz="1.70"/>
    </inertial>
  </link>
  <joint name="base_joint" type="fixed">
    <parent link="base_footprint"/>
    <child link="base_link"/>
    <origin xyz="0 0 0.0694"/>
  </joint>
  <!-- ===================================================== -->
  <!-- Battery (low + central)                               -->
  <!-- ===================================================== -->
  <link name="battery_link">
    <collision>
      <geometry>
        <box size="0.25 0.20 0.25"/>
      </geometry>
    </collision>
    <inertial>
      <origin xyz="0 0 0"/>
      <mass value="5.0"/>
      <inertia ixx="1e-4" ixy="0" ixz="0" iyy="1e-4" iyz="0" izz="1e-4"/>
    </inertial>
  </link>
  <joint name="battery_joint" type="fixed">
    <parent link="base_link"/>
    <child link="battery_link"/>
    <origin xyz="0 0 0.18"/>
  </joint>
  <!-- ===================================================== -->
  <!-- Motors                                                -->
  <!-- ===================================================== -->
  <link name="motors_link">
    <collision>
      <geometry>
        <box size="0.20 0.20 0.10"/>
      </geometry>
    </collision>
    <inertial>
      <origin xyz="0 0 0"/>
      <mass value="3.0"/>
      <inertia ixx="1e-4" ixy="0" ixz="0" iyy="1e-4" iyz="0" izz="1e-4"/>
    </inertial>
  </link>
  <joint name="motors_joint" type="fixed">
    <parent link="base_link"/>
    <child link="motors_link"/>
    <origin xyz="0 0 0.10"/>
  </joint>
  <link name="drivewhl_l_link">
    <visual>
      <origin rpy="1.5707963267948966 0 0"/>
      <geometry>
        <cylinder length="0.025" radius="0.0694"/>
      </geometry>
      <material name="wheel_grey"/>
    </visual>
    <collision>
      <origin rpy="1.5707963267948966 0 0"/>
      <geometry>
        <cylinder length="0.025" radius="0.0694"/>
      </geometry>
    </collision>
    <inertial>
      <mass value="1.0"/>
      <inertia ixx="0.002" ixy="0" ixz="0" iyy="0.002" iyz="0" izz="0.004"/>
    </inertial>
  </link>
  <gazebo reference="drivewhl_l_link">
    <mu1>0.9</mu1>
    <mu2>0.7</mu2>
  </gazebo>
  <joint name="drivewhl_l_joint" type="continuous">
    <parent link="base_link"/>
    <child link="drivewhl_l_link"/>
    <origin xyz="0 0.1011 0"/>
    <axis xyz="0 1 0"/>
    <dynamics damping="0.05"/>
  </joint>
  <link name="drivewhl_r_link">
    <visual>
      <origin rpy="1.5707963267948966 0 0"/>
      <geometry>
        <cylinder length="0.025" radius="0.0694"/>
      </geometry>
      <material name="wheel_grey"/>
    </visual>
    <collision>
      <origin rpy="1.5707963267948966 0 0"/>
      <geometry>
        <cylinder length="0.025" radius="0.0694"/>
      </geometry>
    </collision>
    <inertial>
      <mass value="1.0"/>
      <inertia ixx="0.002" ixy="0" ixz="0" iyy="0.002" iyz="0" izz="0.004"/>
    </inertial>
  </link>
  <gazebo reference="drivewhl_r_link">
    <mu1>0.9</mu1>
    <mu2>0.7</mu2>
  </gazebo>
  <joint name="drivewhl_r_joint" type="continuous">
    <parent link="base_link"/>
    <child link="drivewhl_r_link"/>
    <origin xyz="0 -0.1011 0"/>
    <axis xyz="0 1 0"/>
    <dynamics damping="0.05"/>
  </joint>
  <!-- ===================================================== -->
  <!-- Ball caster (4 cm sphere)                              -->
  <!-- ===================================================== -->
  <link name="ball_caster_link">
    <visual>
      <geometry>
        <sphere radius="0.04"/>
      </geometry>
      <material name="wheel_grey"/>
    </visual>
    <collision>
      <geometry>
        <sphere radius="0.04"/>
      </geometry>
    </collision>
    <inertial>
      <origin xyz="0 0 0"/>
      <mass value="0.5"/>
      <inertia ixx="1e-4" ixy="0" ixz="0" iyy="1e-4" iyz="0" izz="1e-4"/>
    </inertial>
  </link>
  <gazebo reference="ball_caster_link">
    <mu1>0.2</mu1>
    <mu2>0.2</mu2>
  </gazebo>
  <joint name="ball_caster_joint" type="fixed">
    <parent link="base_link"/>
    <child link="ball_caster_link"/>
    <origin xyz="-0.3 0 -0.029400000000000003"/>
  </joint>
  <!-- ===================================================== -->
  <!-- Sensors                                               -->
  <!-- ===================================================== -->
  <!-- started at 0.565 raised by 20 cm to clear body       -->
  <link name="base_laser">
    <inertial>
      <origin xyz="0 0 0"/>
      <mass value="0.05"/>
      <inertia ixx="1e-4" ixy="0" ixz="0" iyy="1e-4" iyz="0" izz="1e-4"/>
    </inertial>
  </link>
  <joint name="base_laser_joint" type="fixed">
    <parent link="base_link"/>
    <child link="base_laser"/>
    <origin rpy="0 0 0" xyz="-0.112 0 0.53"/>
  </joint>
  <gazebo reference="base_laser">
    <sensor name="ld06_lidar" type="gpu_lidar">
      <update_rate>10</update_rate>
      <always_on>true</always_on>
      <topic>/ld06/scan</topic>
      <pose>0 0 0 0 0 0</pose>
      <visualize>true</visualize>
      <gz_frame_id>base_laser</gz_frame_id>
      <frame_id>base_laser</frame_id>
      <lidar>
        <scan>
          <horizontal>
            <samples>360</samples>
            <min_angle>-3.14159</min_angle>
            <max_angle>3.14159</max_angle>
          </horizontal>
        </scan>
        <range>
          <min>0.02</min>
          <max>12.0</max>
        </range>
      </lidar>
    </sensor>
  </gazebo>
  <link name="eyecam_link">
    <inertial>
      <origin xyz="0 0 0"/>
      <mass value="0.05"/>
      <inertia ixx="1e-4" ixy="0" ixz="0" iyy="1e-4" iyz="0" izz="1e-4"/>
    </inertial>
  </link>
  <joint name="eyecam_joint" type="fixed">
    <parent link="base_link"/>
    <child link="eyecam_link"/>
    <origin xyz="0.366 0 0.67"/>
  </joint>
  <link name="3dcam_link">
    <inertial>
      <origin xyz="0 0 0"/>
      <mass value="0.1"/>
      <inertia ixx="1e-4" ixy="0" ixz="0" iyy="1e-4" iyz="0" izz="1e-4"/>
    </inertial>
  </link>
  <joint name="3dcam_joint" type="fixed">
    <parent link="base_link"/>
    <child link="3dcam_link"/>
    <origin xyz="0.206 0 0.255"/>
  </joint>
  <!-- ******************** LEFT EAR ****************************** -->
  <link name="l_ear_link">
    <!-- Visual (for Gazebo visualisation) -->
    <visual name="l_ear_visual">
      <origin rpy="0 0 0" xyz="0 0 0"/>
      <geometry>
        <box size="0.015 0.02 0.03"/>
      </geometry>
      <material name="k9_ear_emissive">
        <ambient>0 0 0 1</ambient>
        <diffuse>0 0 0 1</diffuse>
        <emissive>0 0 0 1</emissive>
        <!-- will be driven by Gazebo -->
      </material>
    </visual>
    <inertial>
      <origin xyz="0 0 0"/>
      <mass value="0.05"/>
      <inertia ixx="1e-4" ixy="0" ixz="0" iyy="1e-4" iyz="0" izz="1e-4"/>
    </inertial>
  </link>
  <gazebo reference="l_ear_link">
    <sensor name="l_ear_tof" type="gpu_lidar">
      <pose>0.0075 0 0 0 0 0</pose>
      <update_rate>30</update_rate>
      <always_on>true</always_on>
      <visualize>true</visualize>
      <topic>/l_ear/scan</topic>
      <gz_frame_id>l_ear_link</gz_frame_id>
      <frame_id>l_ear_link</frame_id>
      <lidar>
        <scan>
          <horizontal>
            <samples>3</samples>
            <resolution>1</resolution>
            <min_angle>-0.005</min_angle>
            <max_angle>0.005</max_angle>
          </horizontal>
        </scan>
        <range>
          <min>0.02</min>
          <max>2.0</max>
          <resolution>0.001</resolution>
        </range>
      </lidar>
    </sensor>
  </gazebo>
  <joint name="l_ear_joint" type="revolute">
    <parent link="base_link"/>
    <child link="l_ear_link"/>
    <origin rpy="0.0 0.25 0.0" xyz="0.27 0.0425 0.67"/>
    <axis xyz="0 0 1"/>
    <limit effort="2.0" lower="-0.2" upper="0.6" velocity="10"/>
    <dynamics damping="0.01" friction="0.01"/>
  </joint>
  <!-- ******************** RIGHT EAR ****************************** -->
  <link name="r_ear_link">
    <visual name="r_ear_visual">
      <origin rpy="0 0 0" xyz="0 0 0"/>
      <geometry>
        <box size="0.015 0.02 0.03"/>
      </geometry>
      <material name="k9_ear_emissive">
        <ambient>0 0 0 1</ambient>
        <diffuse>0 0 0 1</diffuse>
        <emissive>0 0 0 1</emissive>
      </material>
    </visual>
    <inertial>
      <origin xyz="0 0 0"/>
      <mass value="0.05"/>
      <inertia ixx="1e-4" ixy="0" ixz="0" iyy="1e-4" iyz="0" izz="1e-4"/>
    </inertial>
  </link>
  <gazebo reference="r_ear_link">
    <sensor name="r_ear_tof" type="gpu_lidar">
      <pose>0.0075 0 0 0 0 0</pose>
      <update_rate>30</update_rate>
      <always_on>true</always_on>
      <visualize>true</visualize>
      <topic>/r_ear/scan</topic>
      <gz_frame_id>r_ear_link</gz_frame_id>
      <frame_id>r_ear_link</frame_id>
      <lidar>
        <scan>
          <horizontal>
            <samples>3</samples>
            <resolution>1</resolution>
            <min_angle>-0.005</min_angle>
            <max_angle>0.005</max_angle>
          </horizontal>
        </scan>
        <range>
          <min>0.02</min>
          <max>2.0</max>
          <resolution>0.001</resolution>
        </range>
      </lidar>
    </sensor>
  </gazebo>
  <joint name="r_ear_joint" type="revolute">
    <parent link="base_link"/>
    <child link="r_ear_link"/>
    <origin rpy="0.0 0.25 0.0" xyz="0.27 -0.0425 0.67"/>
    <axis xyz="0 0 1"/>
    <limit effort="2.0" lower="-0.6" upper="0.2" velocity="10"/>
    <dynamics damping="0.01" friction="0.01"/>
  </joint>
  <!-- ===================================================== -->
  <!-- Ear Joint Movement (gz-sim, Jazzy)                    -->
  <!-- ===================================================== -->
  <ros2_control name="K9EarsSystem" type="system">
    <hardware>
      <plugin>gz_ros2_control/GazeboSimSystem</plugin>
    </hardware>
    <joint name="l_ear_joint">
      <command_interface name="position"/>
      <state_interface name="position"/>
      <state_interface name="velocity"/>
    </joint>
    <joint name="r_ear_joint">
      <command_interface name="position"/>
      <state_interface name="position"/>
      <state_interface name="velocity"/>
    </joint>
  </ros2_control>
  <!-- ===================================================== -->
  <!-- IMU (gz-sim, Jazzy)                                   -->
  <!-- ===================================================== -->
  <!-- A tiny link to carry the IMU sensor -->
  <link name="imu_link">
    <inertial>
      <origin rpy="0 0 0" xyz="0 0 0"/>
      <mass value="0.02"/>
      <inertia ixx="1e-6" ixy="0" ixz="0" iyy="1e-6" iyz="0" izz="1e-6"/>
    </inertial>
  </link>
  <joint name="imu_link_joint" type="fixed">
    <parent link="base_link"/>
    <child link="imu_link"/>
    <origin rpy="0 0 0" xyz="0 0 0.16"/>
  </joint>
  <!-- Gazebo Sim sensor definition -->
  <gazebo reference="imu_link">
    <sensor name="imu_link_sensor" type="imu">
      <topic>/k9/imu</topic>
      <always_on>true</always_on>
      <visualize>false</visualize>
      <update_rate>200</update_rate>
      <!-- Noise model (tune these to feel like your BNO080) -->
      <imu>
        <angular_velocity>
          <x>
            <noise type="gaussian">
              <mean>0.0</mean>
              <stddev>0.001</stddev>
              <bias_mean>0.0</bias_mean>
              <bias_stddev>0.0</bias_stddev>
            </noise>
          </x>
          <y>
            <noise type="gaussian">
              <mean>0.0</mean>
              <stddev>0.001</stddev>
              <bias_mean>0.0</bias_mean>
              <bias_stddev>0.0</bias_stddev>
            </noise>
          </y>
          <z>
            <noise type="gaussian">
              <mean>0.0</mean>
              <stddev>0.001</stddev>
              <bias_mean>0.0</bias_mean>
              <bias_stddev>0.0</bias_stddev>
            </noise>
          </z>
        </angular_velocity>
        <linear_acceleration>
          <x>
            <noise type="gaussian">
              <mean>0.0</mean>
              <stddev>0.01</stddev>
              <bias_mean>0.0</bias_mean>
              <bias_stddev>0.0</bias_stddev>
            </noise>
          </x>
          <y>
            <noise type="gaussian">
              <mean>0.0</mean>
              <stddev>0.01</stddev>
              <bias_mean>0.0</bias_mean>
              <bias_stddev>0.0</bias_stddev>
            </noise>
          </y>
          <z>
            <noise type="gaussian">
              <mean>0.0</mean>
              <stddev>0.01</stddev>
              <bias_mean>0.0</bias_mean>
              <bias_stddev>0.0</bias_stddev>
            </noise>
          </z>
        </linear_acceleration>
      </imu>
    </sensor>
  </gazebo>
  <!-- A tiny link to carry the camera sensor -->
  <link name="oakd_link">
    <inertial>
      <origin rpy="0 0 0" xyz="0 0 0"/>
      <mass value="0.05"/>
      <inertia ixx="1e-5" ixy="0" ixz="0" iyy="1e-5" iyz="0" izz="1e-5"/>
    </inertial>
  </link>
  <joint name="oakd_link_joint" type="fixed">
    <parent link="base_link"/>
    <child link="oakd_link"/>
    <origin rpy="0 0 0" xyz="0.26 0 0.255"/>
  </joint>
  <!-- Depth frame used by Gazebo / depthimage_to_laserscan -->
  <link name="camera_depth_frame"/>
  <joint name="camera_depth_frame_joint" type="fixed">
    <parent link="oakd_link"/>
    <!-- or oakd_link / 3dcam_link, whichever is your camera body -->
    <child link="camera_depth_frame"/>
    <origin rpy="-1.5707963267948966 0 -1.5707963267948966" xyz="0 0 0"/>
  </joint>
  <gazebo reference="oakd_link">
    <sensor name="oakd_link_rgbd" type="rgbd_camera">
      <always_on>true</always_on>
      <visualize>false</visualize>
      <update_rate>30</update_rate>
      <topic>/oak</topic>
      <camera>
        <horizontal_fov>1.3962634</horizontal_fov>
        <image>
          <width>640</width>
          <height>400</height>
        </image>
        <clip>
          <near>0.2</near>
          <far>8.0</far>
        </clip>
        <noise>
          <type>gaussian</type>
          <mean>0.0</mean>
          <stddev>0.003</stddev>
        </noise>
      </camera>
    </sensor>
  </gazebo>
  <!-- ===================================================== -->
  <!-- Gazebo Diff Drive (gz-sim, Jazzy)                     -->
  <!-- ===================================================== -->
  <gazebo>
    <plugin filename="gz-sim-diff-drive-system" name="gz::sim::systems::DiffDrive">
      <left_joint>drivewhl_l_joint</left_joint>
      <right_joint>drivewhl_r_joint</right_joint>
      <wheel_separation>0.2022</wheel_separation>
      <wheel_radius>0.0694</wheel_radius>
      <max_linear_velocity>1.4</max_linear_velocity>
      <max_angular_velocity>0.63</max_angular_velocity>
      <!-- CHANGED: lower accel also caps braking decel (less "nose dive") -->
      <max_linear_acceleration>0.28</max_linear_acceleration>
      <max_angular_acceleration>0.21</max_angular_acceleration>
      <topic>/cmd_vel</topic>
      <odom_topic>/odom</odom_topic>
      <odom_publish_frequency>50</odom_publish_frequency>
      <tf_topic>/tf</tf_topic>
      <frame_id>odom</frame_id>
      <child_frame_id>base_footprint</child_frame_id>
    </plugin>
  </gazebo>
  <gazebo>
    <plugin filename="/opt/ros/jazzy/lib/libgz_ros2_control-system.so" name="gz_ros2_control::GazeboSimROS2ControlPlugin">
      <parameters>/home/hopkira/Documents/GitHub/k9-gazebo/src/k9_robot/src/description/ear_controllers.yaml</parameters>
    </plugin>
  </gazebo>
</robot>
