<?xml version="1.0" ?>
<!-- =================================================================================== -->
<!-- |    This document was autogenerated by xacro from k9.urdf.xacro                  | -->
<!-- |    EDITING THIS FILE BY HAND IS NOT RECOMMENDED                                 | -->
<!-- =================================================================================== -->
<robot name="k9_robot">
  <!-- ===================== Materials ===================== -->
  <material name="K9_grey">
    <!-- NOTE: the model is largely transparent in RViz -->
    <color rgba="0.25 0.25 0.25 1.0"/>
  </material>
  <material name="perspex_red">
    <color rgba="1.0 0.1 0.1 1.0"/>
  </material>
  <material name="wheel_grey">
    <color rgba="0.7 0.7 0.7 1.0"/>
  </material>
  <material name="white">
    <color rgba="1.0 1.0 1.0 1.0"/>
  </material>
  <!-- axle behind swivel -->
  <!-- ===================== Base frames ===================== -->
  <link name="base_footprint"/>
  <link name="base_link">
    <visual>
      <origin rpy="0 0 3.141592653589793" xyz="-0.5 1.905 0"/>
      <geometry>
        <mesh filename="file:///home/hopkira/Documents/GitHub/k9-gazebo/src/k9_description/urdf/k9.stl" scale="0.01 0.01 0.01"/>
      </geometry>
      <material name="K9_grey"/>
    </visual>
    <!-- Collision layout avoids wheels and mirrors head/body -->
    <collision>
      <origin rpy="0.0 0.0 0.0" xyz="-0.119 0.0 0.285"/>
      <geometry>
        <box size="0.89 0.49 0.49"/>
      </geometry>
    </collision>
    <collision>
      <origin rpy="0.0 0.0 0.0" xyz="0.336 0.0 0.6125"/>
      <geometry>
        <box size="0.43 0.18 0.295"/>
      </geometry>
    </collision>
    <inertial>
      <!-- Shift COM slightly behind wheel contact line to prevent nose tipping -->
      <origin rpy="0 0 0" xyz="-0.02 0 0.15"/>
      <mass value="25.0"/>
      <inertia ixx="0.98230" ixy="0.0" ixz="0.0" iyy="2.4" iyz="0.0" izz="2.03021"/>
    </inertial>
  </link>
  <joint name="base_joint" type="fixed">
    <parent link="base_footprint"/>
    <child link="base_link"/>
    <origin rpy="0 0 0" xyz="0.0 0.0 0.06939"/>
  </joint>
  <link name="drivewhl_l_link">
    <visual>
      <origin rpy="1.5707963267948966 0 0" xyz="0 0 0"/>
      <geometry>
        <cylinder length="0.025" radius="0.06939"/>
      </geometry>
      <material name="wheel_grey"/>
    </visual>
    <collision>
      <origin rpy="1.5707963267948966 0 0" xyz="0 0 0"/>
      <geometry>
        <cylinder length="0.025" radius="0.06939"/>
      </geometry>
    </collision>
    <inertial>
      <origin rpy="0 0 0" xyz="0 0 0"/>
      <mass value="1.0"/>
      <inertia ixx="0.0012558263583333329" ixy="0" ixz="0" iyy="0.0012558263583333329" iyz="0" izz="0.0024074860499999997"/>
    </inertial>
  </link>
  <joint name="drivewhl_l_joint" type="continuous">
    <parent link="base_footprint"/>
    <child link="drivewhl_l_link"/>
    <!-- wheel center is wheel_radius above ground -->
    <origin rpy="0 0 0" xyz="0.0 0.1011 0.06939"/>
    <axis xyz="0 1 0"/>
    <dynamics damping="0.05" friction="0.0"/>
  </joint>
  <link name="drivewhl_r_link">
    <visual>
      <origin rpy="1.5707963267948966 0 0" xyz="0 0 0"/>
      <geometry>
        <cylinder length="0.025" radius="0.06939"/>
      </geometry>
      <material name="wheel_grey"/>
    </visual>
    <collision>
      <origin rpy="1.5707963267948966 0 0" xyz="0 0 0"/>
      <geometry>
        <cylinder length="0.025" radius="0.06939"/>
      </geometry>
    </collision>
    <inertial>
      <origin rpy="0 0 0" xyz="0 0 0"/>
      <mass value="1.0"/>
      <inertia ixx="0.0012558263583333329" ixy="0" ixz="0" iyy="0.0012558263583333329" iyz="0" izz="0.0024074860499999997"/>
    </inertial>
  </link>
  <joint name="drivewhl_r_joint" type="continuous">
    <parent link="base_footprint"/>
    <child link="drivewhl_r_link"/>
    <!-- wheel center is wheel_radius above ground -->
    <origin rpy="0 0 0" xyz="0.0 -0.1011 0.06939"/>
    <axis xyz="0 1 0"/>
    <dynamics damping="0.05" friction="0.0"/>
  </joint>
  <!-- ===================== Swivel caster ===================== -->
  <link name="caster_swivel_link">
    <visual>
      <origin rpy="0 0 0" xyz="0 0 0"/>
      <geometry>
        <cylinder length="0.03" radius="0.008"/>
      </geometry>
      <material name="wheel_grey"/>
    </visual>
    <collision>
      <origin rpy="0 0 0" xyz="0 0 0"/>
      <geometry>
        <cylinder length="0.03" radius="0.008"/>
      </geometry>
    </collision>
    <inertial>
      <origin rpy="0 0 0" xyz="0 0 0"/>
      <mass value="0.15"/>
      <inertia ixx="1.365e-05" ixy="0" ixz="0" iyy="1.365e-05" iyz="0" izz="4.8e-06"/>
    </inertial>
  </link>
  <joint name="caster_swivel_joint" type="continuous">
    <parent link="base_link"/>
    <child link="caster_swivel_link"/>
    <origin rpy="0 0 0" xyz="-0.298 0.0 -0.05138999999999999"/>
    <axis xyz="0 0 1"/>
    <dynamics damping="0.8" friction="0.0"/>
  </joint>
  <link name="caster_wheel_link">
    <visual>
      <origin rpy="1.5707963267948966 0 0" xyz="0 0 0"/>
      <geometry>
        <cylinder length="0.012" radius="0.02"/>
      </geometry>
      <material name="wheel_grey"/>
    </visual>
    <collision>
      <origin rpy="1.5707963267948966 0 0" xyz="0 0 0"/>
      <geometry>
        <cylinder length="0.012" radius="0.02"/>
      </geometry>
    </collision>
    <inertial>
      <origin rpy="0 0 0" xyz="0 0 0"/>
      <mass value="0.1"/>
      <inertia ixx="1.12e-05" ixy="0" ixz="0" iyy="1.12e-05" iyz="0" izz="2e-05"/>
    </inertial>
  </link>
  <joint name="caster_wheel_joint" type="continuous">
    <parent link="caster_swivel_link"/>
    <child link="caster_wheel_link"/>
    <origin rpy="0 0 0" xyz="-0.018 0 0"/>
    <axis xyz="0 1 0"/>
    <dynamics damping="0.10" friction="0.0"/>
  </joint>
  <!-- ===================== Sensors / accessories (with inertials) ===================== -->
  <link name="lidar_link">
    <inertial>
      <origin rpy="0 0 0" xyz="0 0 0"/>
      <mass value="0.05"/>
      <inertia ixx="1e-05" ixy="0" ixz="0" iyy="1e-05" iyz="0" izz="1e-05"/>
    </inertial>
  </link>
  <joint name="lidar_joint" type="fixed">
    <parent link="base_link"/>
    <child link="lidar_link"/>
    <origin rpy="0.0 0.0 0.0" xyz="-0.112 0.0 0.565"/>
  </joint>
  <link name="eyecam_link">
    <inertial>
      <origin rpy="0 0 0" xyz="0 0 0"/>
      <mass value="0.05"/>
      <inertia ixx="1e-05" ixy="0" ixz="0" iyy="1e-05" iyz="0" izz="1e-05"/>
    </inertial>
  </link>
  <joint name="eyecam_joint" type="fixed">
    <parent link="base_link"/>
    <child link="eyecam_link"/>
    <origin rpy="0.0 0.0 0.0" xyz="0.366 0.0 0.67"/>
  </joint>
  <link name="3dcam_link">
    <inertial>
      <origin rpy="0 0 0" xyz="0 0 0"/>
      <mass value="0.1"/>
      <inertia ixx="2e-05" ixy="0" ixz="0" iyy="2e-05" iyz="0" izz="2e-05"/>
    </inertial>
  </link>
  <joint name="3dcam_joint" type="fixed">
    <parent link="base_link"/>
    <child link="3dcam_link"/>
    <origin rpy="0.0 0.0 0.0" xyz="0.206 0.0 0.255"/>
  </joint>
  <link name="l_ear_link">
    <inertial>
      <origin rpy="0 0 0" xyz="0 0 0"/>
      <mass value="0.02"/>
      <inertia ixx="5e-06" ixy="0" ixz="0" iyy="5e-06" iyz="0" izz="5e-06"/>
    </inertial>
  </link>
  <joint name="l_ear_joint" type="fixed">
    <parent link="base_link"/>
    <child link="l_ear_link"/>
    <origin rpy="0.0 0.65 0.0" xyz="0.35 0.045 0.725"/>
  </joint>
  <link name="r_ear_link">
    <inertial>
      <origin rpy="0 0 0" xyz="0 0 0"/>
      <mass value="0.02"/>
      <inertia ixx="5e-06" ixy="0" ixz="0" iyy="5e-06" iyz="0" izz="5e-06"/>
    </inertial>
  </link>
  <joint name="r_ear_joint" type="fixed">
    <parent link="base_link"/>
    <child link="r_ear_link"/>
    <origin rpy="0.0 0.65 0.0" xyz="0.35 -0.045 0.725"/>
  </joint>
  <!-- ===================== Gazebo Sim extensions ===================== -->
  <!-- Wheel / caster contact: give the drive wheels explicit friction too -->
  <gazebo reference="drivewhl_l_link">
    <surface>
      <friction>
        <ode>
          <mu>1.1</mu>
          <mu2>0.9</mu2>
        </ode>
      </friction>
    </surface>
  </gazebo>
  <gazebo reference="drivewhl_r_link">
    <surface>
      <friction>
        <ode>
          <mu>1.1</mu>
          <mu2>0.9</mu2>
        </ode>
      </friction>
    </surface>
  </gazebo>
  <gazebo reference="caster_wheel_link">
    <surface>
      <friction>
        <ode>
          <mu>0.3</mu>
          <mu2>0.15</mu2>
        </ode>
      </friction>
    </surface>
  </gazebo>
  <!-- Gazebo Sim diff-drive system plugin
       NOTE: This plugin consumes /cmd_vel on Gazebo Transport.
       In ROS 2 you typically bridge geometry_msgs/Twist <-> gz.msgs.Twist on /cmd_vel. -->
  <gazebo>
    <plugin filename="gz-sim-diff-drive-system" name="gz::sim::systems::DiffDrive">
      <left_joint>drivewhl_l_joint</left_joint>
      <right_joint>drivewhl_r_joint</right_joint>
      <wheel_separation>0.2022</wheel_separation>
      <wheel_radius>0.06939</wheel_radius>
      <!-- Publish gz odom + tf (bridge if you want ROS topics) -->
      <odom_publish_frequency>50</odom_publish_frequency>
      <!-- Use simple top-level topics to make bridging easy -->
      <topic>/cmd_vel</topic>
      <odom_topic>/odom</odom_topic>
      <tf_topic>/tf</tf_topic>
      <!-- Frame ids inside the gz odometry message -->
      <frame_id>odom</frame_id>
      <child_frame_id>base_footprint</child_frame_id>
    </plugin>
  </gazebo>
</robot>
