<?xml version="1.0" ?>
<robot name="k9_robot" xmlns:xacro="http://ros.org/wiki/xacro">

  <material name="K9 grey">
    <color rgba="0.25 0.25 0.25 0.1" />
  </material>

  <material name="perspex red">
    <color rgba="1.0 0.1 0.1 1.0" />
  </material>

  <material name="wheel grey">
    <color rgba="0.7 0.7 0.7 1.0"/>
  </material>

  <material name="white">
    <color rgba="1.0 1.0 1.0 1.0"/>
  </material>

  <!-- ****************** ROBOT CONSTANTS *******************************  -->
  <!-- https://answers.gazebosim.org//question/24436/how-to-specify-urdf-link-which-attaches-to-world-ground/ -->
  <!-- Define the size of the robot's main chassis in meters -->
  <xacro:property name="base_width" value="0.49"/>
  <xacro:property name="base_length" value="0.81"/>
  <xacro:property name="base_height" value="0.52"/>
	
  <!-- Define the shape of the robot's two front wheels in meters -->
  <xacro:property name="wheel_radius" value="0.06939"/>
  <xacro:property name="wheel_width" value="0.014"/>

  <!-- x-axis points forward, y-axis points to left, z-axis points upwards -->
  <!-- Define the gap between the wheel and chassis along y-axis in meters -->
  <xacro:property name="wheel_ygap" value="0.1011"/>

  <!-- Position the wheels along the z-axis -->
  <xacro:property name="wheel_zoff" value="0.03239"/>

  <!-- Position the wheels along the x-axis -->
  <xacro:property name="wheel_xoff" value="0.0"/>

  <!-- Position the castor wheel along the x-axis -->
  <xacro:property name="castor_xoff" value="-0.298"/>

  <!-- Position the castor wheel along the z-axis -->
  <xacro:property name="castor_z_offset" value="-0.02"/>

  <!-- Define intertial property macros  -->
  <xacro:macro name="box_inertia" params="m w h d">
    <inertial>
      <origin xyz="0 0 0" rpy="${pi/2} 0 ${pi/2}"/>
      <mass value="${m}"/>
      <inertia ixx="${(m/12) * (h*h + d*d)}" ixy="0.0" ixz="0.0" iyy="${(m/12) * (w*w + d*d)}" iyz="0.0" izz="${(m/12) * (w*w + h*h)}"/>
    </inertial>
  </xacro:macro>

  <xacro:macro name="cylinder_inertia" params="m r h">
    <inertial>
      <origin xyz="0 0 0" rpy="${pi/2} 0 0" />
      <mass value="${m}"/>
      <inertia ixx="${(m/12) * (3*r*r + h*h)}" ixy = "0" ixz = "0" iyy="${(m/12) * (3*r*r + h*h)}" iyz = "0" izz="${(m/2) * (r*r)}"/>
    </inertial>
  </xacro:macro>

  <xacro:macro name="sphere_inertia" params="m r">
    <inertial>
      <mass value="${m}"/>
      <inertia ixx="${(2/5) * m * (r*r)}" ixy="0.0" ixz="0.0" iyy="${(2/5) * m * (r*r)}" iyz="0.0" izz="${(2/5) * m * (r*r)}"/>
    </inertial>
  </xacro:macro>

  <!-- ****************** ROBOT BASE FOOTPRINT ***************************  -->
  <!-- Define the center of the main robot chassis projected on the ground -->	
  <link name="base_footprint"/>

  <!-- ********************** ROBOT BASE *********************************  -->
  <link name="base_link">
    <visual>
      <origin xyz="-0.5 1.905 0" rpy="0 0 ${pi}"/>
      <geometry>
        <mesh filename="package://k9_robot/description/k9.stl" scale = "0.01 0.01 0.01" />
      </geometry>
      <material name="K9 grey" />
    </visual>

    <collision>
      <origin xyz="-0.119 0.0 0.297" rpy="0.0 0.0 0.0"/>
      <geometry>
        <box size="0.89 0.49 0.52"/>
      </geometry>
    </collision>

    <collision>
      <origin xyz="0.336 0.0 0.6125" rpy="0.0 0.0 0.0"/>
      <geometry>
        <box size="0.43 0.18 0.295"/>
      </geometry>
    </collision>

    <xacro:box_inertia m="40.0" w="${base_width}" d="${base_length}" h="${base_height}"/>
    
  </link>

  <gazebo reference="base_link">
    <material name="Perspex red" />
  </gazebo>

  <!-- The base footprint of the robot is located underneath the chassis -->
  <joint name="base_joint" type="fixed">
    <parent link="base_link"/>
    <child link="base_footprint" />
    <origin xyz="0.0 0.0 0.0" rpy="0 0 0"/>
  </joint>

  <!-- *********************** DRIVE WHEELS ******************************  -->

  <xacro:macro name="wheel" params="prefix x_reflect y_reflect">
    <link name="${prefix}_link">
      <visual>
        <origin xyz="${x_reflect*wheel_xoff} ${y_reflect*wheel_ygap} ${wheel_radius}" rpy="${pi/2} 0.0 0.0"/>
        <geometry>
            <cylinder radius="${wheel_radius}" length="${wheel_width}"/>
        </geometry>
        <material name="wheel gray"/>
      </visual>
      <collision>
        <origin xyz="${x_reflect*wheel_xoff} ${y_reflect*wheel_ygap} ${wheel_radius}" rpy="${pi/2} 0.0 0.0"/>
        <geometry>
          <sphere radius="${wheel_radius}"/>
        </geometry>
      </collision>
      <xacro:cylinder_inertia m="110.5" r="${wheel_radius}" h="${wheel_width}"/>
    </link>
    <!-- Connect the wheels to the base_link at the appropriate location, and 
         define a continuous joint to allow the wheels to freely rotate about
         an axis -->
    <joint name="${prefix}_joint" type="revolute">
      <parent link="base_link"/>
      <child link="${prefix}_link"/>
      <origin xyz="${x_reflect*wheel_xoff} ${y_reflect*wheel_ygap} ${wheel_radius}" rpy="0 0 0"/>
      <limit upper="${pi}" lower="${-pi}" effort="30" velocity="5.0"/>
      <axis xyz="0 1 0"/>
    </joint>
  </xacro:macro>

  <!-- Instantiate two wheels using the macro we just made through the 
       xacro:wheel tags. We also define the parameters to have one wheel
       on both sides at the back of our robot (i.e. x_reflect=-1). -->
  <xacro:wheel prefix="drivewhl_l" x_reflect="-1" y_reflect="1" />
  <xacro:wheel prefix="drivewhl_r" x_reflect="-1" y_reflect="-1" />

  <!-- *********************** castor WHEEL ******************************  -->
  <!-- We add a castor wheel. It will be modeled as sphere.
       We define the wheel’s geometry, material and the joint to connect it to 
       base_link at the appropriate location. -->
  <link name="rear_castor">
    <visual>
      <geometry>
        <sphere radius="0.02"/>
      </geometry>
      <material name="White" />
    </visual>
    <collision>
      <origin xyz="0.0 0.0 0.0" rpy="0.0 0.0 0.0"/>
      <geometry>
        <sphere radius="0.02"/>
      </geometry>
    </collision>
    <xacro:sphere_inertia m="10.05" r="0.02"/>
  </link>

  <gazebo reference="rear_castor">
    <mu1>0.01</mu1>
    <mu2>0.01</mu2>
    <material name="white"/>
  </gazebo>

  <joint name="castor_joint" type="fixed">
    <parent link="base_link"/>
    <child link="rear_castor"/>
    <origin xyz="-0.298 0.0 0.02" rpy="0 0 0"/>
  </joint>
  
  <!-- *********************** LIDAR ********************************  -->
  <link name="lidar_link"/>
  
  <joint name="lidar_joint" type="fixed">
    <parent link="base_link"/>
    <child link="lidar_link"/>
    <origin xyz="-0.112	0.0	0.565" rpy="0.0 0.0 0.0"/>
  </joint>

  
  <!-- ******************** EYE CAMERA ******************************  -->
  <link name="eyecam_link"/>
 
  <joint name="eyecam_joint" type="fixed">
    <parent link="base_link"/>
    <child link="eyecam_link"/>
    <origin xyz="0.366 0.0 0.67" rpy="0.0 0.0 0.0"/>
  </joint>

 

  <!-- ******************** 3D CAMERA ******************************  -->
  <link name="3dcam_link"/>
  
  <joint name="3dcam_joint" type="fixed">
    <parent link="base_link"/>
    <child link="3dcam_link"/>
    <origin xyz="0.206 0.0 0.255" rpy="0.0 0.0 0.0"/>
  </joint>

  

  <!-- ******************** LEFT EAR ******************************  -->
  <link name="l_ear_link"/>
 
  <joint name="l_ear_joint" type="fixed">
    <parent link="base_link"/>
    <child link="l_ear_link"/>
    <origin xyz="0.35 0.045 0.725" rpy="0.0 0.65 0.0"/>
  </joint>

 

  <!-- ******************** RIGHT EAR ******************************  -->
  <link name="r_ear_link"/> 

  <joint name="r_ear_joint" type="fixed">
    <parent link="base_link"/>
    <child link="r_ear_link"/>
    <origin xyz="0.35 -0.045 0.725" rpy="0.0 0.65 0.0"/>
  </joint>


</robot>